Workbook

Sheet 2023
A1: Individual Selection Time | B1: Group Selection Time | C1: Selection
A2: 45029.75 | B2: 45027.708 | C2: Mudd - 66
A3: 45028.787 | B3: 45027.708 | C3: Clark III - 224
A4: 45028.785 | B4: 45027.708 | C4: Smiley - 218
A5: 45028.721 | B5: 45027.708 | C5: Clark I - CL-I 116 - 116B
A6: 45029.715 | B6: 45027.708 | C6: Harwood - 106
A7: 45027.76 | B7: 45027.708 | C7: Clark III - 304
A8: 45027.852 | B8: 45027.708 | C8: Dialynas - DLNS 230 - 234
A9: 45027.781 | B9: 45027.708 | C9: Sontag - SNTG 130 - 132
A10: 45027.727 | B10: 45027.708 | C10: Sontag - SNTG 260 - 261
A11: 45028.854 | B11: 45027.708 | C11: Clark III - 315
A12: 45027.835 | B12: 45027.708 | C12: Dialynas - DLNS 320 - 323
A13: 45030.373 | B13: 45027.708
A14: 45028.79 | B14: 45027.708 | C14: Smiley - 215
A15: 45027.769 | B15: 45027.708 | C15: Dialynas - DLNS 350 - 353
A16: 45028.8 | B16: 45027.708 | C16: Walker - WALK 738-739 - 738
A17: 45027.721 | B17: 45027.708 | C17: Dialynas - DLNS 220 - 224
A18: 45028.727 | B18: 45027.708 | C18: Clark I - CL-I 130 - 130B
A19: 45028.796 | B19: 45027.708 | C19: Walker - WALK 648-649 - 649
A20: 45028.775 | B20: 45027.708 | C20: Smiley - 211
A21: 45027.873 | B21: 45027.708 | C21: Clark III - 105
A22: 45027.798 | B22: 45027.71 | C22: Clark III - 103
A23: 45027.796 | B23: 45027.71 | C23: Sontag - SNTG 150 - 152
A24: 45028.75 | B24: 45027.71 | C24: Clark III - 101
A25: 45029.771 | B25: 45027.71 | C25: Harwood - 230
... A59: 45028.725 | B59: 45027.713 | C59: Norton - 12
A60: 45029.851 | B60: 45027.713
A61: 45027.812 | B61: 45027.713 | C61: Clark III - 225
A62: 45027.769 | B62: 45027.713 | C62: Sontag - SNTG 330 - 335
A63: 45027.906 | B63: 45027.713 | C63: Sontag - SNTG 260 - 264
A64: 45028.713 | B64: 45027.715 | C64: Walker - WALK 634 635 656 - 656
A65: 45028.792 | B65: 45027.715 | C65: Smiley - 203
A66: 45028.823 | B66: 45027.715 | C66: Clark I - CL-I 110 - 110A
A67: 45027.817 | B67: 45027.715 | C67: Clark I - CL-I 209 - 209A
A68: 45030.373 | B68: 45027.715
A69: 45029.838 | B69: 45027.715
A70: 45027.8 | B70: 45027.715 | C70: Clark I - CL-I 117 - 117B
A71: 45030.373 | B71: 45027.715
A72: 45029.717 | B72: 45027.715 | C72: Harwood - 164
A73: 45028.833 | B73: 45027.715 | C73: Walker - WALK 646 647 653 - 647
...

Sheet 2024
A1: Individual Selection Time | B1: Group Selection Time | C1: Selection
A2: 45392.833 | B2: 45391.708 | C2: Clark I - CL-I 203 - 203B
A3: 45391.84 | B3: 45391.708 | C3: Clark III - 221
A4: 45391.89 | B4: 45391.708 | C4: Walker - WALK 636-637 - 637
A5: 45392.742 | B5: 45391.708 | C5: Walker - WALK 750-751 - 751
A6: 45392.765 | B6: 45391.708 | C6: Walker - WALK 750-751 - 750
A7: 45391.85 | B7: 45391.708 | C7: Sontag - SNTG 150 - 152
A8: 45392.767 | B8: 45391.708 | C8: Smiley - 102
A9: 45391.792 | B9: 45391.708 | C9: Clark V - CL-V 409-412 - 410
A10: 45391.833 | B10: 45391.708 | C10: Dialynas - DLNS 320 - 323
A11: 45391.719 | B11: 45391.708 | C11: Sontag - SNTG 210 - 212
A12: 45391.881 | B12: 45391.708 | C12: Sontag - SNTG 240 - 242
A13: 45391.781 | B13: 45391.708 | C13: Sontag - SNTG 260 - 262
A14: 45391.792 | B14: 45391.708 | C14: Clark I - CL-I 125 - 125B
A15: 45393.796 | B15: 45391.708
A16: 45391.838 | B16: 45391.708 | C16: Clark I - CL-I 101 - 101B
A17: 45391.717 | B17: 45391.708 | C17: Dialynas - DLNS 310 - 314
A18: 45392.777 | B18: 45391.71 | C18: Smiley - 219
A19: 45392.74 | B19: 45391.71 | C19: Lawry - LWRY C1 - C16
A20: 45391.742 | B20: 45391.71 | C20: Clark III - 211
A21: 45392.815 | B21: 45391.71 | C21: Smiley - 222
A22: 45392.796 | B22: 45391.71 | C22: Sontag - SNTG 260 - 263
A23: 45391.8 | B23: 45391.71 | C23: Sontag - SNTG 110 - 112
A24: 45391.775 | B24: 45391.71 | C24: Dialynas - DLNS 240 - 241
A25: 45392.775 | B25: 45391.71 | C25: Smiley - 208
A26: 45392.733 | B26: 45391.71 | C26: Clark I - CL-I 122 - 122B
A27: 45391.892 | B27: 45391.71 | C27: Clark V - CL-V 413-416 - 416
... A30: 45391.76 | B30: 45391.71 | C30: Sontag - SNTG 310 - 311
A31: No Selection Time Issued | B31: 45391.71 | C31: Blaisdell - 111
A32: 45391.748 | B32: 45391.71 | C32: Clark V - CL-V 455-458 - 455
A33: 45392.79 | B33: 45391.71 | C33: Walker - WALK 610-611 - 611
A34: 45391.725 | B34: 45391.71 | C34: Sontag - SNTG 120 - 121
A35: 45391.812 | B35: 45391.71 | C35: Sontag - SNTG 330 - 331
A36: 45391.894 | B36: 45391.71 | C36: Lawry - LWRY B2 - B21
A37: 45392.75 | B37: 45391.71 | C37: Walker - WALK 644-645 - 644
A38: 45392.787 | B38: 45391.71 | C38: Smiley - 221
A39: 45392.746 | B39: 45391.71 | C39: Walker - WALK 738-739 - 739
A40: 45392.785 | B40: 45391.713 | C40: Clark I - CL-I 110 - 110A
A41: 45391.852 | B41: 45391.713 | C41: Walker - 717
A42: 45391.785 | B42: 45391.713 | C42: Clark III - 308
...

Sheet 2025
A1: Individual Selection Time | B1: Group Selection Time | C1: Selection
A2: 45755.887 | B2: 45755.708 | C2: Clark V - CL-V 433-434 - 433
A3: 45755.708 | B3: 45755.708 | C3: Clark V - CL-V 433-434 - 434
A4: 45755.883 | B4: 45755.708 | C4: Sontag - SNTG 230 - 231
A5: 45755.827 | B5: 45755.708 | C5: Sontag - SNTG 230 - 232
A6: 45755.765 | B6: 45755.708 | C6: Sontag - SNTG 230 - 233
A7: 45755.892 | B7: 45755.708 | C7: Sontag - SNTG 230 - 234
A8: 45755.708 | B8: 45755.708 | C8: Sontag - SNTG 230 - 235
A9: 45755.894 | B9: 45755.708 | C9: Sontag - SNTG 230 - 236
A10: 45755.865 | B10: 45755.708 | C10: Sontag - SNTG 260 - 261
A11: 45755.708 | B11: 45755.708 | C11: Sontag - SNTG 260 - 262
A12: 45755.802 | B12: 45755.708 | C12: Sontag - SNTG 260 - 263
A13: 45755.89 | B13: 45755.708 | C13: Sontag - SNTG 260 - 264
... A551: 45757.829 | B551: 45757.829 | C551: Harwood - 120
A552: 45755.717 | B552: No Selection Time Issued | C552: Clark III - 100
A553: 45755.873 | B553: No Selection Time Issued | C553: Clark III - 102
A554: 45755.721 | B554: No Selection Time Issued | C554: Clark III - 105
A555: 45755.815 | B555: No Selection Time Issued | C555: Clark III - 107
A556: 45755.79 | B556: No Selection Time Issued | C556: Clark III - 114
A557: 45755.775 | B557: No Selection Time Issued | C557: Clark III - 122
A558: 45755.748 | B558: No Selection Time Issued | C558: Clark III - 200
A559: 45755.785 | B559: No Selection Time Issued | C559: Clark III - 201
A560: 45755.762 | B560: No Selection Time Issued | C560: Clark III - 202
A561: 45755.871 | B561: No Selection Time Issued | C561: Clark III - 203
A562: 45755.885 | B562: No Selection Time Issued | C562: Clark III - 204
A563: 45755.867 | B563: No Selection Time Issued | C563: Clark III - 205
... A761: 45755.85 | B761: No Selection Time Issued | C761: Walker - 733
A762: No Selection Time Issued | B762: No Selection Time Issued
A763: 45757.727 | B763: No Selection Time Issued
A764: 45757.783 | B764: No Selection Time Issued
A765: 45757.821 | B765: No Selection Time Issued
A766: 45757.817 | B766: No Selection Time Issued
A767: 45757.823 | B767: No Selection Time Issued
A768: No Selection Time Issued | B768: No Selection Time Issued
A769: No Selection Time Issued | B769: No Selection Time Issued
A770: No Selection Time Issued | B770: No Selection Time Issued
A771: No Selection Time Issued | B771: No Selection Time Issued
A772: No Selection Time Issued | B772: No Selection Time Issued
A773: No Selection Time Issued | B773: No Selection Time Issued
A774: 45757.825 | B774: No Selection Time Issued
...

Sheet Sq. Ft & Room Type
A1: Building Name | B1: Room Number | C1: Square Footage | D1: Room Type
A2: Sontag | B2: 314 | C2: 154 | D2: Single (Suited)
A3: Sontag | B3: 321 | C3: 135 | D3: Single (Suited)
A4: Sontag | B4: 303 | C4: 150 | D4: Single (Suited)
A5: Sontag | B5: 331 | C5: 139 | D5: Single (Suited)
A6: Sontag | B6: 322 | C6: 151 | D6: Single (Suited)
A7: Sontag | B7: 312 | C7: 147 | D7: Single (Suited)
A8: Sontag | B8: 332 | C8: 143 | D8: Single (Suited)
A9: Sontag | B9: 313 | C9: 136 | D9: Single (Suited)
A10: Sontag | B10: 336 | C10: 152 | D10: Single (Suited)
A11: Sontag | B11: 302 | C11: 137 | D11: Single (Suited)
A12: Sontag | B12: 301 | C12: 133 | D12: Single (Suited)
A13: Sontag | B13: 323 | C13: 137 | D13: Single (Suited)
... A80: Clark V | B80: 433 | C80: 148 | D80: Single (Suited)
A81: Clark V | B81: S02A | C81: 162 | D81: Single (Suited)
A82: Clark V | B82: 443 | C82: 181 | D82: Single (Suited)
A83: Clark V | B83: 426 | C83: 147 | D83: Single (Suited)
A84: Clark V | B84: 446 | C84: 200 | D84: Single (Suited)
A85: Clark V | B85: 432 | C85: 144 | D85: Single (Suited)
A86: Clark V | B86: 423 | C86: 144 | D86: Single (Suited)
A87: Clark V | B87: 442 | C87: 147 | D87: Single (Suited)
A88: Clark V | B88: 417 | C88: 147 | D88: Single (Suited)
A89: Clark V | B89: 438 | C89: 152 | D89: Single (Suited)
A90: Clark V | B90: S03A | C90: 163 | D90: Single (Suited)
A91: Clark V | B91: 436 | C91: 147 | D91: Single (Suited)
A92: Clark V | B92: 403 | C92: 147 | D92: Single (Suited)
A93: Clark V | B93: 409 | C93: 147 | D93: Single (Suited)
A94: Clark V | B94: 406 | C94: 147 | D94: Single (Suited)
A95: Clark V | B95: S04A | C95: 163 | D95: Single (Suited)
A96: Clark V | B96: 411 | C96: 146 | D96: Single (Suited)
A97: Clark V | B97: 412 | C97: 146 | D97: Single (Suited)
A98: Clark V | B98: 425 | C98: 141 | D98: Single (Suited)
A99: Clark V | B99: 420 | C99: 147 | D99: Single (Suited)
A100: Clark V | B100: 430 | C100: 150 | D100: Single (Suited)
A101: Clark V | B101: S05B | C101: 136 | D101: Single (Suited)
A102: Clark V | B102: 427 | C102: 179 | D102: Single (Suited)
A103: Clark V | B103: 413 | C103: 150 | D103: Single (Suited)
A104: Clark V | B104: 437 | C104: 183 | D104: Single (Suited)
A105: Clark V | B105: 401 | C105: 149 | D105: Single (Suited)
A106: Clark V | B106: 418 | C106: 147 | D106: Single (Suited)
...

Sheet Room Capacity
A1: Building Name | B1: Level | C1: Hall / Suite | D1: Room Number | E1: Occupancy(Overflow)
A2: Blaisdell | B2: 1 | D2: 110 | E2: 1 (0)
A3: Blaisdell | B3: 1 | D3: 111 | E3: 2 (0)
A4: Blaisdell | B4: 1 | D4: 112 | E4: 3 (0)
A5: Blaisdell | B5: 1 | D5: 113 | E5: 2 (0)
A6: Blaisdell | B6: 1 | D6: 115 | E6: 2 (0)
A7: Blaisdell | B7: 1 | C7: BLSD 116 | D7: 116A | E7: 1 (0)
A8: Blaisdell | B8: 1 | C8: BLSD 116 | D8: 116B | E8: 1 (0)
A9: Blaisdell | B9: 1 | D9: 117 | E9: 3 (0)
A10: Blaisdell | B10: 1 | D10: 118 | E10: 2 (0)
A11: Blaisdell | B11: 1 | D11: 118A | E11: 1 (0)
A12: Blaisdell | B12: 1 | D12: 119 | E12: 1 (0)
A13: Blaisdell | B13: 1 | D13: 120 | E13: 2 (0)
A14: Blaisdell | B14: 1 | D14: 121 | E14: 2 (0)
A15: Blaisdell | B15: 1 | D15: 122 | E15: 1 (0)
A16: Blaisdell | B16: 1 | D16: 123 | E16: 2 (0)
A17: Blaisdell | B17: 1 | D17: 124 | E17: 2 (0)
A18: Blaisdell | B18: 1 | D18: 125 | E18: 2 (0)
A19: Blaisdell | B19: 1 | D19: 126 | E19: 2 (0)
A20: Blaisdell | B20: 1 | D20: 127 | E20: 1 (0)
A21: Blaisdell | B21: 1 | D21: 128 | E21: 2 (0)
A22: Blaisdell | B22: 1 | D22: 129 | E22: 2 (0)
A23: Blaisdell | B23: 1 | C23: BLSD 130-131 | D23: 130 | E23: 1 (0)
A24: Blaisdell | B24: 1 | C24: BLSD 130-131 | D24: 131 | E24: 1 (0)
A25: Blaisdell | B25: 1 | D25: 132 | E25: 2 (0)
A26: Blaisdell | B26: 1 | D26: 133 | E26: 2 (0)
A27: Blaisdell | B27: 1 | D27: 134 | E27: 2 (0)
A28: Blaisdell | B28: 1 | D28: 135 | E28: 1 (0)
A29: Blaisdell | B29: 1 | D29: 136 | E29: 2 (0)
A30: Blaisdell | B30: 1 | D30: 137 | E30: 2 (0)
A31: Blaisdell | B31: 1 | D31: 138 | E31: 2 (0)
A32: Blaisdell | B32: 1 | D32: 139 | E32: 2 (0)
A33: Blaisdell | B33: 1 | D33: 140 | E33: 2 (0)
A34: Blaisdell | B34: 1 | D34: 141 | E34: 2 (0)
A35: Blaisdell | B35: 1 | D35: 142 | E35: 2 (0)
A36: Blaisdell | B36: 1 | D36: 143 | E36: 2 (0)
A37: Blaisdell | B37: 1 | D37: L-1 | E37: 3 (0)
A38: Blaisdell | B38: 2 | D38: 201 | E38: 3 (0)
A39: Blaisdell | B39: 2 | D39: 202 | E39: 2 (0)
A40: Blaisdell | B40: 2 | D40: 203 | E40: 1 (0)
...

Sheet Master
A1: Dorm Name | B1: Square Footage of Unique Dorms | C1: Unique Dorms | D1: Selection Time (Individual) 2023 | E1: Selection Time (Group) 2023 | F1: 2023 Selection Time | G1: Selection Time (Individual) 2024 | H1: Selection Time (Group) 2024 | I1: 2024 Selection Time | J1: Selection Time (Individual) 2025 | K1: Selection Time (Group) 2025 | L1: 2025 Selection Time | M1: Occupancy | N1: AC
A2: Blaisdell - 10 | B2: 201 | C2: {=_xlfn.LET( _xlpm.x,_xlfn.UNIQUE(_xlfn._xlws.FILTER(A2:A2454,A2:A2454<>"")), _xlfn.SORTBY( _xlpm.x, _xlfn.TEXTBEFORE(_xlpm.x," - "),1, --_xlfn.TEXTAFTER(_xlpm.x," - "),1 ) )} -> Blaisdell - 2 | D2: =_xlfn.XLOOKUP(C2,'2023'!C:C,'2023'!A:A,"") -> 45029.787 | E2: =_xlfn.XLOOKUP(C2,'2023'!C:C,'2023'!B:B,"") -> 45027.79 | G2: =_xlfn.XLOOKUP(C2,'2024'!C:C,'2024'!A:A,"") | H2: =_xlfn.XLOOKUP(C3,'2024'!C:C,'2024'!B:B,"") | I2: =_xlfn.LET( _xlpm.ind,G2, _xlpm.grp,H2, IF(AND(NOT(ISNUMBER(_xlpm.ind)),NOT(ISNUMBER(_xlpm.grp))),"", MIN(IF(ISNUMBER(_xlpm.ind),_xlpm.ind,1E+99),IF(ISNUMBER(_xlpm.grp),_xlpm.grp,1E+99)) ) ) | J2: =_xlfn.XLOOKUP(C2,'2025'!C:C,'2025'!A:A,"") | K2: =_xlfn.XLOOKUP(C2,'2025'!C:C,'2025'!B:B,"") | L2: =_xlfn.LET(_xlpm.ind,J2,_xlpm.grp,K2,IF(AND(NOT(ISNUMBER(_xlpm.ind)),NOT(ISNUMBER(_xlpm.grp))),"",MIN(IF(ISNUMBER(_xlpm.ind),_xlpm.ind,1E+99),IF(ISNUMBER(_xlpm.grp),_xlpm.grp,1E+99)))) | M2: {=IFERROR(_xlfn.LET( _xlpm.x,TRIM(C2), _xlpm.dorm,TRIM(_xlfn.TEXTBEFORE(_xlpm.x," - ")), _xlpm.room,TRIM(_xlfn.TEXTAFTER(_xlpm.x," - ",-1)), _xlpm.occ,_xlfn.XLOOKUP( 1, (TRIM('Room Capacity'!A:A)=_xlpm.dorm)*(TRIM('Room Capacity'!D:D&"")=_xlpm.room), 'Room Capacity'!E:E, "" ), VALUE(_xlfn.TEXTBEFORE(_xlpm.occ," ")) ),"")} -> 2 | N2: =OR(_xlfn.TEXTBEFORE(C2," - ")="Blaisdell",_xlfn.TEXTBEFORE(C2," - ")="Mudd",_xlfn.TEXTBEFORE(C2," - ")="Dialynas",_xlfn.TEXTBEFORE(C2," - ")="Sontag") -> TRUE
A3: Blaisdell - 10 | B3: 159 | C3: Blaisdell - 3 | D3: =_xlfn.XLOOKUP(C3,'2023'!C:C,'2023'!A:A,"") -> 45029.715 | E3: =_xlfn.XLOOKUP(C3,'2023'!C:C,'2023'!B:B,"") -> No Selection Time Issued | F3: =_xlfn.LET( _xlpm.ind,D3, _xlpm.grp,E3, IF(AND(NOT(ISNUMBER(_xlpm.ind)),NOT(ISNUMBER(_xlpm.grp))),"", MIN(IF(ISNUMBER(_xlpm.ind),_xlpm.ind,1E+99),IF(ISNUMBER(_xlpm.grp),_xlpm.grp,1E+99)) ) ) -> 45029.715 | G3: =_xlfn.XLOOKUP(C3,'2024'!C:C,'2024'!A:A,"") | H3: =_xlfn.XLOOKUP(C4,'2024'!C:C,'2024'!B:B,"") | I3: =_xlfn.LET( _xlpm.ind,G3, _xlpm.grp,H3, IF(AND(NOT(ISNUMBER(_xlpm.ind)),NOT(ISNUMBER(_xlpm.grp))),"", MIN(IF(ISNUMBER(_xlpm.ind),_xlpm.ind,1E+99),IF(ISNUMBER(_xlpm.grp),_xlpm.grp,1E+99)) ) ) | J3: =_xlfn.XLOOKUP(C3,'2025'!C:C,'2025'!A:A,"") | K3: =_xlfn.XLOOKUP(C3,'2025'!C:C,'2025'!B:B,"") | L3: =_xlfn.LET(_xlpm.ind,J3,_xlpm.grp,K3,IF(AND(NOT(ISNUMBER(_xlpm.ind)),NOT(ISNUMBER(_xlpm.grp))),"",MIN(IF(ISNUMBER(_xlpm.ind),_xlpm.ind,1E+99),IF(ISNUMBER(_xlpm.grp),_xlpm.grp,1E+99)))) | M3: {=IFERROR(_xlfn.LET( _xlpm.x,TRIM(C3), _xlpm.dorm,TRIM(_xlfn.TEXTBEFORE(_xlpm.x," - ")), _xlpm.room,TRIM(_xlfn.TEXTAFTER(_xlpm.x," - ",-1)), _xlpm.occ,_xlfn.XLOOKUP( 1, (TRIM('Room Capacity'!A:A)=_xlpm.dorm)*(TRIM('Room Capacity'!D:D&"")=_xlpm.room), 'Room Capacity'!E:E, "" ), VALUE(_xlfn.TEXTBEFORE(_xlpm.occ," ")) ),"")} -> 1 | N3: =OR(_xlfn.TEXTBEFORE(C3," - ")="Blaisdell",_xlfn.TEXTBEFORE(C3," - ")="Mudd",_xlfn.TEXTBEFORE(C3," - ")="Dialynas",_xlfn.TEXTBEFORE(C3," - ")="Sontag") -> TRUE
A4: Blaisdell - 10 | B4: 183 | C4: Blaisdell - 4 | D4: =_xlfn.XLOOKUP(C4,'2023'!C:C,'2023'!A:A,"") -> 45029.815 | E4: =_xlfn.XLOOKUP(C4,'2023'!C:C,'2023'!B:B,"") -> 45029.738 | F4: =_xlfn.LET( _xlpm.ind,D4, _xlpm.grp,E4, IF(AND(NOT(ISNUMBER(_xlpm.ind)),NOT(ISNUMBER(_xlpm.grp))),"", MIN(IF(ISNUMBER(_xlpm.ind),_xlpm.ind,1E+99),IF(ISNUMBER(_xlpm.grp),_xlpm.grp,1E+99)) ) ) -> 45029.738 | G4: =_xlfn.XLOOKUP(C4,'2024'!C:C,'2024'!A:A,"") | H4: =_xlfn.XLOOKUP(C5,'2024'!C:C,'2024'!B:B,"") | I4: =_xlfn.LET( _xlpm.ind,G4, _xlpm.grp,H4, IF(AND(NOT(ISNUMBER(_xlpm.ind)),NOT(ISNUMBER(_xlpm.grp))),"", MIN(IF(ISNUMBER(_xlpm.ind),_xlpm.ind,1E+99),IF(ISNUMBER(_xlpm.grp),_xlpm.grp,1E+99)) ) ) | J4: =_xlfn.XLOOKUP(C4,'2025'!C:C,'2025'!A:A,"") | K4: =_xlfn.XLOOKUP(C4,'2025'!C:C,'2025'!B:B,"") | L4: =_xlfn.LET(_xlpm.ind,J4,_xlpm.grp,K4,IF(AND(NOT(ISNUMBER(_xlpm.ind)),NOT(ISNUMBER(_xlpm.grp))),"",MIN(IF(ISNUMBER(_xlpm.ind),_xlpm.ind,1E+99),IF(ISNUMBER(_xlpm.grp),_xlpm.grp,1E+99)))) | M4: {=IFERROR(_xlfn.LET( _xlpm.x,TRIM(C4), _xlpm.dorm,TRIM(_xlfn.TEXTBEFORE(_xlpm.x," - ")), _xlpm.room,TRIM(_xlfn.TEXTAFTER(_xlpm.x," - ",-1)), _xlpm.occ,_xlfn.XLOOKUP( 1, (TRIM('Room Capacity'!A:A)=_xlpm.dorm)*(TRIM('Room Capacity'!D:D&"")=_xlpm.room), 'Room Capacity'!E:E, "" ), VALUE(_xlfn.TEXTBEFORE(_xlpm.occ," ")) ),"")} -> 2 | N4: =OR(_xlfn.TEXTBEFORE(C4," - ")="Blaisdell",_xlfn.TEXTBEFORE(C4," - ")="Mudd",_xlfn.TEXTBEFORE(C4," - ")="Dialynas",_xlfn.TEXTBEFORE(C4," - ")="Sontag") -> TRUE
A5: Blaisdell - 111 | B5: 183 | C5: Blaisdell - 6 | D5: =_xlfn.XLOOKUP(C5,'2023'!C:C,'2023'!A:A,"") -> 45029.821 | E5: =_xlfn.XLOOKUP(C5,'2023'!C:C,'2023'!B:B,"") -> No Selection Time Issued | F5: =_xlfn.LET( _xlpm.ind,D5, _xlpm.grp,E5, IF(AND(NOT(ISNUMBER(_xlpm.ind)),NOT(ISNUMBER(_xlpm.grp))),"", MIN(IF(ISNUMBER(_xlpm.ind),_xlpm.ind,1E+99),IF(ISNUMBER(_xlpm.grp),_xlpm.grp,1E+99)) ) ) -> 45029.821 | G5: =_xlfn.XLOOKUP(C5,'2024'!C:C,'2024'!A:A,"") | H5: =_xlfn.XLOOKUP(C6,'2024'!C:C,'2024'!B:B,"") | I5: =_xlfn.LET( _xlpm.ind,G5, _xlpm.grp,H5, IF(AND(NOT(ISNUMBER(_xlpm.ind)),NOT(ISNUMBER(_xlpm.grp))),"", MIN(IF(ISNUMBER(_xlpm.ind),_xlpm.ind,1E+99),IF(ISNUMBER(_xlpm.grp),_xlpm.grp,1E+99)) ) ) | J5: =_xlfn.XLOOKUP(C5,'2025'!C:C,'2025'!A:A,"") | K5: =_xlfn.XLOOKUP(C5,'2025'!C:C,'2025'!B:B,"") | L5: =_xlfn.LET(_xlpm.ind,J5,_xlpm.grp,K5,IF(AND(NOT(ISNUMBER(_xlpm.ind)),NOT(ISNUMBER(_xlpm.grp))),"",MIN(IF(ISNUMBER(_xlpm.ind),_xlpm.ind,1E+99),IF(ISNUMBER(_xlpm.grp),_xlpm.grp,1E+99)))) | M5: {=IFERROR(_xlfn.LET( _xlpm.x,TRIM(C5), _xlpm.dorm,TRIM(_xlfn.TEXTBEFORE(_xlpm.x," - ")), _xlpm.room,TRIM(_xlfn.TEXTAFTER(_xlpm.x," - ",-1)), _xlpm.occ,_xlfn.XLOOKUP( 1, (TRIM('Room Capacity'!A:A)=_xlpm.dorm)*(TRIM('Room Capacity'!D:D&"")=_xlpm.room), 'Room Capacity'!E:E, "" ), VALUE(_xlfn.TEXTBEFORE(_xlpm.occ," ")) ),"")} -> 2 | N5: =OR(_xlfn.TEXTBEFORE(C5," - ")="Blaisdell",_xlfn.TEXTBEFORE(C5," - ")="Mudd",_xlfn.TEXTBEFORE(C5," - ")="Dialynas",_xlfn.TEXTBEFORE(C5," - ")="Sontag") -> TRUE
A6: Blaisdell - 111 | B6: 175 | C6: Blaisdell - 8 | D6: =_xlfn.XLOOKUP(C6,'2023'!C:C,'2023'!A:A,"") -> 45029.823 | E6: =_xlfn.XLOOKUP(C6,'2023'!C:C,'2023'!B:B,"") -> 45027.723 | F6: =_xlfn.LET( _xlpm.ind,D6, _xlpm.grp,E6, IF(AND(NOT(ISNUMBER(_xlpm.ind)),NOT(ISNUMBER(_xlpm.grp))),"", MIN(IF(ISNUMBER(_xlpm.ind),_xlpm.ind,1E+99),IF(ISNUMBER(_xlpm.grp),_xlpm.grp,1E+99)) ) ) -> 45027.723 | G6: =_xlfn.XLOOKUP(C6,'2024'!C:C,'2024'!A:A,"") | H6: =_xlfn.XLOOKUP(C7,'2024'!C:C,'2024'!B:B,"") | I6: =_xlfn.LET( _xlpm.ind,G6, _xlpm.grp,H6, IF(AND(NOT(ISNUMBER(_xlpm.ind)),NOT(ISNUMBER(_xlpm.grp))),"", MIN(IF(ISNUMBER(_xlpm.ind),_xlpm.ind,1E+99),IF(ISNUMBER(_xlpm.grp),_xlpm.grp,1E+99)) ) ) | J6: =_xlfn.XLOOKUP(C6,'2025'!C:C,'2025'!A:A,"") | K6: =_xlfn.XLOOKUP(C6,'2025'!C:C,'2025'!B:B,"") | L6: =_xlfn.LET(_xlpm.ind,J6,_xlpm.grp,K6,IF(AND(NOT(ISNUMBER(_xlpm.ind)),NOT(ISNUMBER(_xlpm.grp))),"",MIN(IF(ISNUMBER(_xlpm.ind),_xlpm.ind,1E+99),IF(ISNUMBER(_xlpm.grp),_xlpm.grp,1E+99)))) | M6: {=IFERROR(_xlfn.LET( _xlpm.x,TRIM(C6), _xlpm.dorm,TRIM(_xlfn.TEXTBEFORE(_xlpm.x," - ")), _xlpm.room,TRIM(_xlfn.TEXTAFTER(_xlpm.x," - ",-1)), _xlpm.occ,_xlfn.XLOOKUP( 1, (TRIM('Room Capacity'!A:A)=_xlpm.dorm)*(TRIM('Room Capacity'!D:D&"")=_xlpm.room), 'Room Capacity'!E:E, "" ), VALUE(_xlfn.TEXTBEFORE(_xlpm.occ," ")) ),"")} -> 2 | N6: =OR(_xlfn.TEXTBEFORE(C6," - ")="Blaisdell",_xlfn.TEXTBEFORE(C6," - ")="Mudd",_xlfn.TEXTBEFORE(C6," - ")="Dialynas",_xlfn.TEXTBEFORE(C6," - ")="Sontag") -> TRUE
A7: Blaisdell - 12 | B7: 332 | C7: Blaisdell - 10 | D7: =_xlfn.XLOOKUP(C7,'2023'!C:C,'2023'!A:A,"") -> 45029.838 | E7: =_xlfn.XLOOKUP(C7,'2023'!C:C,'2023'!B:B,"") -> 45027.71 | F7: =_xlfn.LET( _xlpm.ind,D7, _xlpm.grp,E7, IF(AND(NOT(ISNUMBER(_xlpm.ind)),NOT(ISNUMBER(_xlpm.grp))),"", MIN(IF(ISNUMBER(_xlpm.ind),_xlpm.ind,1E+99),IF(ISNUMBER(_xlpm.grp),_xlpm.grp,1E+99)) ) ) -> 45027.71 | G7: =_xlfn.XLOOKUP(C7,'2024'!C:C,'2024'!A:A,"") | H7: =_xlfn.XLOOKUP(C8,'2024'!C:C,'2024'!B:B,"") | I7: =_xlfn.LET( _xlpm.ind,G7, _xlpm.grp,H7, IF(AND(NOT(ISNUMBER(_xlpm.ind)),NOT(ISNUMBER(_xlpm.grp))),"", MIN(IF(ISNUMBER(_xlpm.ind),_xlpm.ind,1E+99),IF(ISNUMBER(_xlpm.grp),_xlpm.grp,1E+99)) ) ) | J7: =_xlfn.XLOOKUP(C7,'2025'!C:C,'2025'!A:A,"") | K7: =_xlfn.XLOOKUP(C7,'2025'!C:C,'2025'!B:B,"") | L7: =_xlfn.LET(_xlpm.ind,J7,_xlpm.grp,K7,IF(AND(NOT(ISNUMBER(_xlpm.ind)),NOT(ISNUMBER(_xlpm.grp))),"",MIN(IF(ISNUMBER(_xlpm.ind),_xlpm.ind,1E+99),IF(ISNUMBER(_xlpm.grp),_xlpm.grp,1E+99)))) | M7: {=IFERROR(_xlfn.LET( _xlpm.x,TRIM(C7), _xlpm.dorm,TRIM(_xlfn.TEXTBEFORE(_xlpm.x," - ")), _xlpm.room,TRIM(_xlfn.TEXTAFTER(_xlpm.x," - ",-1)), _xlpm.occ,_xlfn.XLOOKUP( 1, (TRIM('Room Capacity'!A:A)=_xlpm.dorm)*(TRIM('Room Capacity'!D:D&"")=_xlpm.room), 'Room Capacity'!E:E, "" ), VALUE(_xlfn.TEXTBEFORE(_xlpm.occ," ")) ),"")} -> 3 | N7: =OR(_xlfn.TEXTBEFORE(C7," - ")="Blaisdell",_xlfn.TEXTBEFORE(C7," - ")="Mudd",_xlfn.TEXTBEFORE(C7," - ")="Dialynas",_xlfn.TEXTBEFORE(C7," - ")="Sontag") -> TRUE
A8: Blaisdell - 12 | B8: 246 | C8: Blaisdell - 12 | D8: =_xlfn.XLOOKUP(C8,'2023'!C:C,'2023'!A:A,"") -> 45029.802 | E8: =_xlfn.XLOOKUP(C8,'2023'!C:C,'2023'!B:B,"") -> 45027.89 | F8: =_xlfn.LET( _xlpm.ind,D8, _xlpm.grp,E8, IF(AND(NOT(ISNUMBER(_xlpm.ind)),NOT(ISNUMBER(_xlpm.grp))),"", MIN(IF(ISNUMBER(_xlpm.ind),_xlpm.ind,1E+99),IF(ISNUMBER(_xlpm.grp),_xlpm.grp,1E+99)) ) ) -> 45027.89 | G8: =_xlfn.XLOOKUP(C8,'2024'!C:C,'2024'!A:A,"") | H8: =_xlfn.XLOOKUP(C9,'2024'!C:C,'2024'!B:B,"") | I8: =_xlfn.LET( _xlpm.ind,G8, _xlpm.grp,H8, IF(AND(NOT(ISNUMBER(_xlpm.ind)),NOT(ISNUMBER(_xlpm.grp))),"", MIN(IF(ISNUMBER(_xlpm.ind),_xlpm.ind,1E+99),IF(ISNUMBER(_xlpm.grp),_xlpm.grp,1E+99)) ) ) | J8: =_xlfn.XLOOKUP(C8,'2025'!C:C,'2025'!A:A,"") | K8: =_xlfn.XLOOKUP(C8,'2025'!C:C,'2025'!B:B,"") | L8: =_xlfn.LET(_xlpm.ind,J8,_xlpm.grp,K8,IF(AND(NOT(ISNUMBER(_xlpm.ind)),NOT(ISNUMBER(_xlpm.grp))),"",MIN(IF(ISNUMBER(_xlpm.ind),_xlpm.ind,1E+99),IF(ISNUMBER(_xlpm.grp),_xlpm.grp,1E+99)))) | M8: {=IFERROR(_xlfn.LET( _xlpm.x,TRIM(C8), _xlpm.dorm,TRIM(_xlfn.TEXTBEFORE(_xlpm.x," - ")), _xlpm.room,TRIM(_xlfn.TEXTAFTER(_xlpm.x," - ",-1)), _xlpm.occ,_xlfn.XLOOKUP( 1, (TRIM('Room Capacity'!A:A)=_xlpm.dorm)*(TRIM('Room Capacity'!D:D&"")=_xlpm.room), 'Room Capacity'!E:E, "" ), VALUE(_xlfn.TEXTBEFORE(_xlpm.occ," ")) ),"")} -> 2 | N8: =OR(_xlfn.TEXTBEFORE(C8," - ")="Blaisdell",_xlfn.TEXTBEFORE(C8," - ")="Mudd",_xlfn.TEXTBEFORE(C8," - ")="Dialynas",_xlfn.TEXTBEFORE(C8," - ")="Sontag") -> TRUE
A9: Blaisdell - 120 | B9: 164 | C9: Blaisdell - 14 | D9: =_xlfn.XLOOKUP(C9,'2023'!C:C,'2023'!A:A,"") -> 45029.85 | E9: =_xlfn.XLOOKUP(C9,'2023'!C:C,'2023'!B:B,"") -> 45028.798 | F9: =_xlfn.LET( _xlpm.ind,D9, _xlpm.grp,E9, IF(AND(NOT(ISNUMBER(_xlpm.ind)),NOT(ISNUMBER(_xlpm.grp))),"", MIN(IF(ISNUMBER(_xlpm.ind),_xlpm.ind,1E+99),IF(ISNUMBER(_xlpm.grp),_xlpm.grp,1E+99)) ) ) -> 45028.798 | G9: =_xlfn.XLOOKUP(C9,'2024'!C:C,'2024'!A:A,"") | H9: =_xlfn.XLOOKUP(C10,'2024'!C:C,'2024'!B:B,"") | I9: =_xlfn.LET( _xlpm.ind,G9, _xlpm.grp,H9, IF(AND(NOT(ISNUMBER(_xlpm.ind)),NOT(ISNUMBER(_xlpm.grp))),"", MIN(IF(ISNUMBER(_xlpm.ind),_xlpm.ind,1E+99),IF(ISNUMBER(_xlpm.grp),_xlpm.grp,1E+99)) ) ) | J9: =_xlfn.XLOOKUP(C9,'2025'!C:C,'2025'!A:A,"") | K9: =_xlfn.XLOOKUP(C9,'2025'!C:C,'2025'!B:B,"") | L9: =_xlfn.LET(_xlpm.ind,J9,_xlpm.grp,K9,IF(AND(NOT(ISNUMBER(_xlpm.ind)),NOT(ISNUMBER(_xlpm.grp))),"",MIN(IF(ISNUMBER(_xlpm.ind),_xlpm.ind,1E+99),IF(ISNUMBER(_xlpm.grp),_xlpm.grp,1E+99)))) | M9: {=IFERROR(_xlfn.LET( _xlpm.x,TRIM(C9), _xlpm.dorm,TRIM(_xlfn.TEXTBEFORE(_xlpm.x," - ")), _xlpm.room,TRIM(_xlfn.TEXTAFTER(_xlpm.x," - ",-1)), _xlpm.occ,_xlfn.XLOOKUP( 1, (TRIM('Room Capacity'!A:A)=_xlpm.dorm)*(TRIM('Room Capacity'!D:D&"")=_xlpm.room), 'Room Capacity'!E:E, "" ), VALUE(_xlfn.TEXTBEFORE(_xlpm.occ," ")) ),"")} -> 2 | N9: =OR(_xlfn.TEXTBEFORE(C9," - ")="Blaisdell",_xlfn.TEXTBEFORE(C9," - ")="Mudd",_xlfn.TEXTBEFORE(C9," - ")="Dialynas",_xlfn.TEXTBEFORE(C9," - ")="Sontag") -> TRUE
A10: Blaisdell - 120 | B10: 285 | C10: Blaisdell - 16 | D10: =_xlfn.XLOOKUP(C10,'2023'!C:C,'2023'!A:A,"") -> 45029.748 | E10: =_xlfn.XLOOKUP(C10,'2023'!C:C,'2023'!B:B,"") -> 45029.738 | F10: =_xlfn.LET( _xlpm.ind,D10, _xlpm.grp,E10, IF(AND(NOT(ISNUMBER(_xlpm.ind)),NOT(ISNUMBER(_xlpm.grp))),"", MIN(IF(ISNUMBER(_xlpm.ind),_xlpm.ind,1E+99),IF(ISNUMBER(_xlpm.grp),_xlpm.grp,1E+99)) ) ) -> 45029.738 | G10: =_xlfn.XLOOKUP(C10,'2024'!C:C,'2024'!A:A,"") | H10: =_xlfn.XLOOKUP(C11,'2024'!C:C,'2024'!B:B,"") | I10: =_xlfn.LET( _xlpm.ind,G10, _xlpm.grp,H10, IF(AND(NOT(ISNUMBER(_xlpm.ind)),NOT(ISNUMBER(_xlpm.grp))),"", MIN(IF(ISNUMBER(_xlpm.ind),_xlpm.ind,1E+99),IF(ISNUMBER(_xlpm.grp),_xlpm.grp,1E+99)) ) ) | J10: =_xlfn.XLOOKUP(C10,'2025'!C:C,'2025'!A:A,"") | K10: =_xlfn.XLOOKUP(C10,'2025'!C:C,'2025'!B:B,"") | L10: =_xlfn.LET(_xlpm.ind,J10,_xlpm.grp,K10,IF(AND(NOT(ISNUMBER(_xlpm.ind)),NOT(ISNUMBER(_xlpm.grp))),"",MIN(IF(ISNUMBER(_xlpm.ind),_xlpm.ind,1E+99),IF(ISNUMBER(_xlpm.grp),_xlpm.grp,1E+99)))) | M10: {=IFERROR(_xlfn.LET( _xlpm.x,TRIM(C10), _xlpm.dorm,TRIM(_xlfn.TEXTBEFORE(_xlpm.x," - ")), _xlpm.room,TRIM(_xlfn.TEXTAFTER(_xlpm.x," - ",-1)), _xlpm.occ,_xlfn.XLOOKUP( 1, (TRIM('Room Capacity'!A:A)=_xlpm.dorm)*(TRIM('Room Capacity'!D:D&"")=_xlpm.room), 'Room Capacity'!E:E, "" ), VALUE(_xlfn.TEXTBEFORE(_xlpm.occ," ")) ),"")} -> 2 | N10: =OR(_xlfn.TEXTBEFORE(C10," - ")="Blaisdell",_xlfn.TEXTBEFORE(C10," - ")="Mudd",_xlfn.TEXTBEFORE(C10," - ")="Dialynas",_xlfn.TEXTBEFORE(C10," - ")="Sontag") -> TRUE
A11: Blaisdell - 14 | B11: 147 | C11: Blaisdell - 17 | D11: =_xlfn.XLOOKUP(C11,'2023'!C:C,'2023'!A:A,"") -> 45029.833 | E11: =_xlfn.XLOOKUP(C11,'2023'!C:C,'2023'!B:B,"") -> 45027.71 | F11: =_xlfn.LET( _xlpm.ind,D11, _xlpm.grp,E11, IF(AND(NOT(ISNUMBER(_xlpm.ind)),NOT(ISNUMBER(_xlpm.grp))),"", MIN(IF(ISNUMBER(_xlpm.ind),_xlpm.ind,1E+99),IF(ISNUMBER(_xlpm.grp),_xlpm.grp,1E+99)) ) ) -> 45027.71 | G11: =_xlfn.XLOOKUP(C11,'2024'!C:C,'2024'!A:A,"") | H11: =_xlfn.XLOOKUP(C12,'2024'!C:C,'2024'!B:B,"") | I11: =_xlfn.LET( _xlpm.ind,G11, _xlpm.grp,H11, IF(AND(NOT(ISNUMBER(_xlpm.ind)),NOT(ISNUMBER(_xlpm.grp))),"", MIN(IF(ISNUMBER(_xlpm.ind),_xlpm.ind,1E+99),IF(ISNUMBER(_xlpm.grp),_xlpm.grp,1E+99)) ) ) | J11: =_xlfn.XLOOKUP(C11,'2025'!C:C,'2025'!A:A,"") | K11: =_xlfn.XLOOKUP(C11,'2025'!C:C,'2025'!B:B,"") | L11: =_xlfn.LET(_xlpm.ind,J11,_xlpm.grp,K11,IF(AND(NOT(ISNUMBER(_xlpm.ind)),NOT(ISNUMBER(_xlpm.grp))),"",MIN(IF(ISNUMBER(_xlpm.ind),_xlpm.ind,1E+99),IF(ISNUMBER(_xlpm.grp),_xlpm.grp,1E+99)))) | M11: {=IFERROR(_xlfn.LET( _xlpm.x,TRIM(C11), _xlpm.dorm,TRIM(_xlfn.TEXTBEFORE(_xlpm.x," - ")), _xlpm.room,TRIM(_xlfn.TEXTAFTER(_xlpm.x," - ",-1)), _xlpm.occ,_xlfn.XLOOKUP( 1, (TRIM('Room Capacity'!A:A)=_xlpm.dorm)*(TRIM('Room Capacity'!D:D&"")=_xlpm.room), 'Room Capacity'!E:E, "" ), VALUE(_xlfn.TEXTBEFORE(_xlpm.occ," ")) ),"")} -> 2 | N11: =OR(_xlfn.TEXTBEFORE(C11," - ")="Blaisdell",_xlfn.TEXTBEFORE(C11," - ")="Mudd",_xlfn.TEXTBEFORE(C11," - ")="Dialynas",_xlfn.TEXTBEFORE(C11," - ")="Sontag") -> TRUE
A12: Blaisdell - 14 | B12: 147 | C12: Blaisdell - 19 | D12: =_xlfn.XLOOKUP(C12,'2023'!C:C,'2023'!A:A,"") -> 45028.719 | E12: =_xlfn.XLOOKUP(C12,'2023'!C:C,'2023'!B:B,"") -> 45027.844 | F12: =_xlfn.LET( _xlpm.ind,D12, _xlpm.grp,E12, IF(AND(NOT(ISNUMBER(_xlpm.ind)),NOT(ISNUMBER(_xlpm.grp))),"", MIN(IF(ISNUMBER(_xlpm.ind),_xlpm.ind,1E+99),IF(ISNUMBER(_xlpm.grp),_xlpm.grp,1E+99)) ) ) -> 45027.844 | G12: =_xlfn.XLOOKUP(C12,'2024'!C:C,'2024'!A:A,"") | H12: =_xlfn.XLOOKUP(C13,'2024'!C:C,'2024'!B:B,"") | I12: =_xlfn.LET( _xlpm.ind,G12, _xlpm.grp,H12, IF(AND(NOT(ISNUMBER(_xlpm.ind)),NOT(ISNUMBER(_xlpm.grp))),"", MIN(IF(ISNUMBER(_xlpm.ind),_xlpm.ind,1E+99),IF(ISNUMBER(_xlpm.grp),_xlpm.grp,1E+99)) ) ) | J12: =_xlfn.XLOOKUP(C12,'2025'!C:C,'2025'!A:A,"") | K12: =_xlfn.XLOOKUP(C12,'2025'!C:C,'2025'!B:B,"") | L12: =_xlfn.LET(_xlpm.ind,J12,_xlpm.grp,K12,IF(AND(NOT(ISNUMBER(_xlpm.ind)),NOT(ISNUMBER(_xlpm.grp))),"",MIN(IF(ISNUMBER(_xlpm.ind),_xlpm.ind,1E+99),IF(ISNUMBER(_xlpm.grp),_xlpm.grp,1E+99)))) | M12: {=IFERROR(_xlfn.LET( _xlpm.x,TRIM(C12), _xlpm.dorm,TRIM(_xlfn.TEXTBEFORE(_xlpm.x," - ")), _xlpm.room,TRIM(_xlfn.TEXTAFTER(_xlpm.x," - ",-1)), _xlpm.occ,_xlfn.XLOOKUP( 1, (TRIM('Room Capacity'!A:A)=_xlpm.dorm)*(TRIM('Room Capacity'!D:D&"")=_xlpm.room), 'Room Capacity'!E:E, "" ), VALUE(_xlfn.TEXTBEFORE(_xlpm.occ," ")) ),"")} -> 1 | N12: =OR(_xlfn.TEXTBEFORE(C12," - ")="Blaisdell",_xlfn.TEXTBEFORE(C12," - ")="Mudd",_xlfn.TEXTBEFORE(C12," - ")="Dialynas",_xlfn.TEXTBEFORE(C12," - ")="Sontag") -> TRUE
A13: Blaisdell - 16 | B13: 162 | C13: Blaisdell - 23 | D13: =_xlfn.XLOOKUP(C13,'2023'!C:C,'2023'!A:A,"") -> 45029.708 | E13: =_xlfn.XLOOKUP(C13,'2023'!C:C,'2023'!B:B,"") -> 45029.779 | F13: =_xlfn.LET( _xlpm.ind,D13, _xlpm.grp,E13, IF(AND(NOT(ISNUMBER(_xlpm.ind)),NOT(ISNUMBER(_xlpm.grp))),"", MIN(IF(ISNUMBER(_xlpm.ind),_xlpm.ind,1E+99),IF(ISNUMBER(_xlpm.grp),_xlpm.grp,1E+99)) ) ) -> 45029.708 | G13: =_xlfn.XLOOKUP(C13,'2024'!C:C,'2024'!A:A,"") | H13: =_xlfn.XLOOKUP(C14,'2024'!C:C,'2024'!B:B,"") | I13: =_xlfn.LET( _xlpm.ind,G13, _xlpm.grp,H13, IF(AND(NOT(ISNUMBER(_xlpm.ind)),NOT(ISNUMBER(_xlpm.grp))),"", MIN(IF(ISNUMBER(_xlpm.ind),_xlpm.ind,1E+99),IF(ISNUMBER(_xlpm.grp),_xlpm.grp,1E+99)) ) ) | J13: =_xlfn.XLOOKUP(C13,'2025'!C:C,'2025'!A:A,"") | K13: =_xlfn.XLOOKUP(C13,'2025'!C:C,'2025'!B:B,"") | L13: =_xlfn.LET(_xlpm.ind,J13,_xlpm.grp,K13,IF(AND(NOT(ISNUMBER(_xlpm.ind)),NOT(ISNUMBER(_xlpm.grp))),"",MIN(IF(ISNUMBER(_xlpm.ind),_xlpm.ind,1E+99),IF(ISNUMBER(_xlpm.grp),_xlpm.grp,1E+99)))) | M13: {=IFERROR(_xlfn.LET( _xlpm.x,TRIM(C13), _xlpm.dorm,TRIM(_xlfn.TEXTBEFORE(_xlpm.x," - ")), _xlpm.room,TRIM(_xlfn.TEXTAFTER(_xlpm.x," - ",-1)), _xlpm.occ,_xlfn.XLOOKUP( 1, (TRIM('Room Capacity'!A:A)=_xlpm.dorm)*(TRIM('Room Capacity'!D:D&"")=_xlpm.room), 'Room Capacity'!E:E, "" ), VALUE(_xlfn.TEXTBEFORE(_xlpm.occ," ")) ),"")} -> 1 | N13: =OR(_xlfn.TEXTBEFORE(C13," - ")="Blaisdell",_xlfn.TEXTBEFORE(C13," - ")="Mudd",_xlfn.TEXTBEFORE(C13," - ")="Dialynas",_xlfn.TEXTBEFORE(C13," - ")="Sontag") -> TRUE
A14: Blaisdell - 16 | B14: 147 | C14: Blaisdell - 25 | D14: =_xlfn.XLOOKUP(C14,'2023'!C:C,'2023'!A:A,"") -> 45029.733 | E14: =_xlfn.XLOOKUP(C14,'2023'!C:C,'2023'!B:B,"") -> 45027.733 | F14: =_xlfn.LET( _xlpm.ind,D14, _xlpm.grp,E14, IF(AND(NOT(ISNUMBER(_xlpm.ind)),NOT(ISNUMBER(_xlpm.grp))),"", MIN(IF(ISNUMBER(_xlpm.ind),_xlpm.ind,1E+99),IF(ISNUMBER(_xlpm.grp),_xlpm.grp,1E+99)) ) ) -> 45027.733 | G14: =_xlfn.XLOOKUP(C14,'2024'!C:C,'2024'!A:A,"") | H14: =_xlfn.XLOOKUP(C15,'2024'!C:C,'2024'!B:B,"") -> 45391.71 | I14: =_xlfn.LET( _xlpm.ind,G14, _xlpm.grp,H14, IF(AND(NOT(ISNUMBER(_xlpm.ind)),NOT(ISNUMBER(_xlpm.grp))),"", MIN(IF(ISNUMBER(_xlpm.ind),_xlpm.ind,1E+99),IF(ISNUMBER(_xlpm.grp),_xlpm.grp,1E+99)) ) ) -> 45391.71 | J14: =_xlfn.XLOOKUP(C14,'2025'!C:C,'2025'!A:A,"") | K14: =_xlfn.XLOOKUP(C14,'2025'!C:C,'2025'!B:B,"") | L14: =_xlfn.LET(_xlpm.ind,J14,_xlpm.grp,K14,IF(AND(NOT(ISNUMBER(_xlpm.ind)),NOT(ISNUMBER(_xlpm.grp))),"",MIN(IF(ISNUMBER(_xlpm.ind),_xlpm.ind,1E+99),IF(ISNUMBER(_xlpm.grp),_xlpm.grp,1E+99)))) | M14: {=IFERROR(_xlfn.LET( _xlpm.x,TRIM(C14), _xlpm.dorm,TRIM(_xlfn.TEXTBEFORE(_xlpm.x," - ")), _xlpm.room,TRIM(_xlfn.TEXTAFTER(_xlpm.x," - ",-1)), _xlpm.occ,_xlfn.XLOOKUP( 1, (TRIM('Room Capacity'!A:A)=_xlpm.dorm)*(TRIM('Room Capacity'!D:D&"")=_xlpm.room), 'Room Capacity'!E:E, "" ), VALUE(_xlfn.TEXTBEFORE(_xlpm.occ," ")) ),"")} -> 2 | N14: =OR(_xlfn.TEXTBEFORE(C14," - ")="Blaisdell",_xlfn.TEXTBEFORE(C14," - ")="Mudd",_xlfn.TEXTBEFORE(C14," - ")="Dialynas",_xlfn.TEXTBEFORE(C14," - ")="Sontag") -> TRUE
... A858: Dialynas - DLNS 110 - 111 | B858: 146 | C858: Walker - WALK 752-753 - 753 | D858: =_xlfn.XLOOKUP(C858,'2023'!C:C,'2023'!A:A,"") -> 45028.75 | E858: =_xlfn.XLOOKUP(C858,'2023'!C:C,'2023'!B:B,"") -> No Selection Time Issued | F858: =_xlfn.LET( _xlpm.ind,D858, _xlpm.grp,E858, IF(AND(NOT(ISNUMBER(_xlpm.ind)),NOT(ISNUMBER(_xlpm.grp))),"", MIN(IF(ISNUMBER(_xlpm.ind),_xlpm.ind,1E+99),IF(ISNUMBER(_xlpm.grp),_xlpm.grp,1E+99)) ) ) -> 45028.75 | G858: =_xlfn.XLOOKUP(C858,'2024'!C:C,'2024'!A:A,"") -> 45392.777 | H858: =_xlfn.XLOOKUP(C859,'2024'!C:C,'2024'!B:B,"") -> 45391.708 | I858: =_xlfn.LET( _xlpm.ind,G858, _xlpm.grp,H858, IF(AND(NOT(ISNUMBER(_xlpm.ind)),NOT(ISNUMBER(_xlpm.grp))),"", MIN(IF(ISNUMBER(_xlpm.ind),_xlpm.ind,1E+99),IF(ISNUMBER(_xlpm.grp),_xlpm.grp,1E+99)) ) ) -> 45391.708 | J858: =_xlfn.XLOOKUP(C858,'2025'!C:C,'2025'!A:A,"") -> 45756.844 | K858: =_xlfn.XLOOKUP(C858,'2025'!C:C,'2025'!B:B,"") -> 45756.738 | L858: =_xlfn.LET(_xlpm.ind,J858,_xlpm.grp,K858,IF(AND(NOT(ISNUMBER(_xlpm.ind)),NOT(ISNUMBER(_xlpm.grp))),"",MIN(IF(ISNUMBER(_xlpm.ind),_xlpm.ind,1E+99),IF(ISNUMBER(_xlpm.grp),_xlpm.grp,1E+99)))) -> 45756.738 | M858: {=IFERROR(_xlfn.LET( _xlpm.x,TRIM(C858), _xlpm.dorm,TRIM(_xlfn.TEXTBEFORE(_xlpm.x," - ")), _xlpm.room,TRIM(_xlfn.TEXTAFTER(_xlpm.x," - ",-1)), _xlpm.occ,_xlfn.XLOOKUP( 1, (TRIM('Room Capacity'!A:A)=_xlpm.dorm)*(TRIM('Room Capacity'!D:D&"")=_xlpm.room), 'Room Capacity'!E:E, "" ), VALUE(_xlfn.TEXTBEFORE(_xlpm.occ," ")) ),"")} -> 1 | N858: =OR(_xlfn.TEXTBEFORE(C858," - ")="Blaisdell",_xlfn.TEXTBEFORE(C858," - ")="Mudd",_xlfn.TEXTBEFORE(C858," - ")="Dialynas",_xlfn.TEXTBEFORE(C858," - ")="Sontag") -> FALSE
A859: Dialynas - DLNS 110 - 112
A860: Dialynas - DLNS 110 - 112
A861: Dialynas - DLNS 110 - 112
A862: Dialynas - DLNS 110 - 113
A863: Dialynas - DLNS 110 - 113
A864: Dialynas - DLNS 110 - 113
A865: Dialynas - DLNS 110 - 116
A866: Dialynas - DLNS 110 - 116
A867: Dialynas - DLNS 110 - 116
A868: Dialynas - DLNS 120 - 121
A869: Dialynas - DLNS 120 - 121
A870: Dialynas - DLNS 120 - 122
... A2357: Walker - WALK 752-753 - 753
